<?xml version="1.0" ?>
<sdf version="1.8">
  <model name="turtlebot3_waffle">
    <pose>0.0 0.0 0.0 0.0 0.0 0.0</pose>

    <link name="base_footprint"/>

    <link name="base_link">
      <inertial>
        <pose>-0.064 0 0.048 0 0 0</pose>
        <inertia>
          <ixx>4.2111447e-02</ixx>
          <ixy>0</ixy>
          <ixz>0</ixz>
          <iyy>4.2111447e-02</iyy>
          <iyz>0</iyz>
          <izz>7.5254874e-02</izz>
        </inertia>
        <mass>1.3729096e+00</mass>
      </inertial>
      <collision name="base_collision">
        <pose>-0.064 0 0.048 0 0 0</pose>
        <geometry>
          <box><size>0.265 0.265 0.089</size></box>
        </geometry>
      </collision>
      <visual name="base_visual">
        <pose>-0.064 0 0 0 0 0</pose>
        <geometry>
          <mesh>
            <uri>file:///opt/ros/humble/share/turtlebot3_description/meshes/bases/waffle_base.stl</uri>
            <scale>0.001 0.001 0.001</scale>
          </mesh>
        </geometry>
        <material>
          <ambient>0.3 0.3 0.3 1</ambient>
          <diffuse>0.3 0.3 0.3 1</diffuse>
        </material>
      </visual>
    </link>

    <!-- IMU -->
    <link name="imu_link">
      <sensor name="tb3_imu" type="imu">
        <always_on>true</always_on>
        <update_rate>200</update_rate>
        <topic>imu</topic>
        <ignition_frame_id>imu_link</ignition_frame_id>
        <imu>
          <angular_velocity>
            <x><noise type="gaussian"><mean>0.0</mean><stddev>2e-4</stddev></noise></x>
            <y><noise type="gaussian"><mean>0.0</mean><stddev>2e-4</stddev></noise></y>
            <z><noise type="gaussian"><mean>0.0</mean><stddev>2e-4</stddev></noise></z>
          </angular_velocity>
          <linear_acceleration>
            <x><noise type="gaussian"><mean>0.0</mean><stddev>1.7e-2</stddev></noise></x>
            <y><noise type="gaussian"><mean>0.0</mean><stddev>1.7e-2</stddev></noise></y>
            <z><noise type="gaussian"><mean>0.0</mean><stddev>1.7e-2</stddev></noise></z>
          </linear_acceleration>
        </imu>
      </sensor>
    </link>

    <!-- LiDAR -->
    <link name="base_scan">
      <inertial>
        <pose>-0.052 0 0.111 0 0 0</pose>
        <inertia>
          <ixx>0.001</ixx><ixy>0</ixy><ixz>0</ixz>
          <iyy>0.001</iyy><iyz>0</iyz><izz>0.001</izz>
        </inertia>
        <mass>0.114</mass>
      </inertial>
      <collision name="lidar_collision">
        <pose>-0.052 0 0.111 0 0 0</pose>
        <geometry><cylinder><radius>0.0508</radius><length>0.055</length></cylinder></geometry>
      </collision>
      <visual name="lidar_visual">
        <pose>-0.064 0 0.121 0 0 0</pose>
        <geometry>
          <mesh>
            <uri>file:///opt/ros/humble/share/turtlebot3_description/meshes/sensors/lds.stl</uri>
            <scale>0.001 0.001 0.001</scale>
          </mesh>
        </geometry>
        <material>
          <ambient>0.1 0.1 0.1 1</ambient>
          <diffuse>0.1 0.1 0.1 1</diffuse>
        </material>
      </visual>
      <sensor name="hls_lfcd_lds" type="gpu_lidar">
        <always_on>true</always_on>
        <visualize>true</visualize>
        <pose>-0.064 0 0.121 0 0 0</pose>
        <update_rate>5</update_rate>
        <topic>scan</topic>
        <ignition_frame_id>base_scan</ignition_frame_id>
        <ray>
          <scan>
            <horizontal>
              <samples>360</samples>
              <resolution>1.0</resolution>
              <min_angle>0.0</min_angle>
              <max_angle>6.28</max_angle>
            </horizontal>
          </scan>
          <range>
            <min>0.12</min>
            <max>3.5</max>
            <resolution>0.015</resolution>
          </range>
          <noise>
            <type>gaussian</type>
            <mean>0.0</mean>
            <stddev>0.01</stddev>
          </noise>
        </ray>
      </sensor>
    </link>

    <!-- Left Wheel -->
    <link name="wheel_left_link">
      <inertial>
        <pose>0.0 0.144 0.023 -1.57 0 0</pose>
        <inertia>
          <ixx>1.8158194e-03</ixx><ixy>0</ixy><ixz>0</ixz>
          <iyy>3.2922126e-03</iyy><iyz>0</iyz><izz>1.8158194e-03</izz>
        </inertia>
        <mass>2.8498940e-02</mass>
      </inertial>
      <collision name="wheel_left_collision">
        <pose>0.0 0.144 0.023 -1.57 0 0</pose>
        <geometry><cylinder><radius>0.033</radius><length>0.018</length></cylinder></geometry>
        <surface>
          <friction><ode><mu>100000</mu><mu2>100000</mu2></ode></friction>
        </surface>
      </collision>
      <visual name="wheel_left_visual">
        <pose>0.0 0.144 0.023 0 0 0</pose>
        <geometry>
          <mesh>
            <uri>file:///opt/ros/humble/share/turtlebot3_description/meshes/wheels/left_tire.stl</uri>
            <scale>0.001 0.001 0.001</scale>
          </mesh>
        </geometry>
        <material>
          <ambient>0.1 0.1 0.1 1</ambient>
          <diffuse>0.1 0.1 0.1 1</diffuse>
        </material>
      </visual>
    </link>

    <!-- Right Wheel -->
    <link name="wheel_right_link">
      <inertial>
        <pose>0.0 -0.144 0.023 -1.57 0 0</pose>
        <inertia>
          <ixx>1.8158194e-03</ixx><ixy>0</ixy><ixz>0</ixz>
          <iyy>3.2922126e-03</iyy><iyz>0</iyz><izz>1.8158194e-03</izz>
        </inertia>
        <mass>2.8498940e-02</mass>
      </inertial>
      <collision name="wheel_right_collision">
        <pose>0.0 -0.144 0.023 -1.57 0 0</pose>
        <geometry><cylinder><radius>0.033</radius><length>0.018</length></cylinder></geometry>
        <surface>
          <friction><ode><mu>100000</mu><mu2>100000</mu2></ode></friction>
        </surface>
      </collision>
      <visual name="wheel_right_visual">
        <pose>0.0 -0.144 0.023 0 0 0</pose>
        <geometry>
          <mesh>
            <uri>file:///opt/ros/humble/share/turtlebot3_description/meshes/wheels/right_tire.stl</uri>
            <scale>0.001 0.001 0.001</scale>
          </mesh>
        </geometry>
        <material>
          <ambient>0.1 0.1 0.1 1</ambient>
          <diffuse>0.1 0.1 0.1 1</diffuse>
        </material>
      </visual>
    </link>

    <!-- Caster wheels -->
    <link name="caster_back_right_link">
      <pose>-0.177 -0.064 -0.004 0 0 0</pose>
      <inertial>
        <mass>0.001</mass>
        <inertia>
          <ixx>0.00001</ixx><ixy>0</ixy><ixz>0</ixz>
          <iyy>0.00001</iyy><iyz>0</iyz><izz>0.00001</izz>
        </inertia>
      </inertial>
      <collision name="collision">
        <geometry><sphere><radius>0.005</radius></sphere></geometry>
      </collision>
    </link>

    <link name="caster_back_left_link">
      <pose>-0.177 0.064 -0.004 0 0 0</pose>
      <inertial>
        <mass>0.001</mass>
        <inertia>
          <ixx>0.00001</ixx><ixy>0</ixy><ixz>0</ixz>
          <iyy>0.00001</iyy><iyz>0</iyz><izz>0.00001</izz>
        </inertia>
      </inertial>
      <collision name="collision">
        <geometry><sphere><radius>0.005</radius></sphere></geometry>
      </collision>
    </link>

    <!-- Camera -->
    <link name="camera_link">
      <pose>0.076 0.0 0.093 0 0 0</pose>
      <inertial>
        <mass>0.035</mass>
        <inertia>
          <ixx>0.001</ixx><ixy>0</ixy><ixz>0</ixz>
          <iyy>0.001</iyy><iyz>0</iyz><izz>0.001</izz>
        </inertia>
      </inertial>
      <visual name="camera_visual">
        <pose>0 0 0 1.5708 0 1.5708</pose>
        <geometry>
          <mesh>
            <uri>file:///opt/ros/humble/share/realsense2_description/meshes/d435.dae</uri>
          </mesh>
        </geometry>
      </visual>
      <sensor name="camera" type="camera">
        <pose>0.02 0 0 0 0 0</pose>
        <always_on>true</always_on>
        <visualize>true</visualize>
        <update_rate>30</update_rate>
        <topic>camera/image_raw</topic>
        <ignition_frame_id>camera_link</ignition_frame_id>
        <camera name="rs_color">
          <camera_info_topic>camera/camera_info</camera_info_topic>
          <horizontal_fov>1.21126</horizontal_fov>
          <image>
            <width>640</width>
            <height>480</height>
            <format>R8G8B8</format>
          </image>
          <clip>
            <near>0.02</near>
            <far>100</far>
          </clip>
          <noise>
            <type>gaussian</type>
            <mean>0.0</mean>
            <stddev>0.007</stddev>
          </noise>
        </camera>
      </sensor>
      <sensor name="depth_camera" type="depth_camera">
        <pose>0.02 0 0 0 0 0</pose>
        <always_on>true</always_on>
        <visualize>false</visualize>
        <update_rate>30</update_rate>
        <topic>camera/depth/image_rect_raw</topic>
        <ignition_frame_id>camera_depth_frame</ignition_frame_id>
        <camera name="rs_depth">
          <camera_info_topic>camera/depth/camera_info</camera_info_topic>
          <horizontal_fov>1.5184</horizontal_fov>
          <image>
            <width>640</width>
            <height>480</height>
            <format>R_FLOAT32</format>
          </image>
          <clip>
            <near>0.02</near>
            <far>10.0</far>
          </clip>
        </camera>
      </sensor>
    </link>

    <!-- Joints -->
    <joint name="base_joint" type="fixed">
      <parent>base_footprint</parent>
      <child>base_link</child>
      <pose>0.0 0.0 0.010 0 0 0</pose>
    </joint>

    <joint name="wheel_left_joint" type="revolute">
      <parent>base_link</parent>
      <child>wheel_left_link</child>
      <pose>0.0 0.144 0.023 -1.57 0 0</pose>
      <axis><xyz>0 0 1</xyz></axis>
    </joint>

    <joint name="wheel_right_joint" type="revolute">
      <parent>base_link</parent>
      <child>wheel_right_link</child>
      <pose>0.0 -0.144 0.023 -1.57 0 0</pose>
      <axis><xyz>0 0 1</xyz></axis>
    </joint>

    <joint name="caster_back_right_joint" type="ball">
      <parent>base_link</parent>
      <child>caster_back_right_link</child>
    </joint>

    <joint name="caster_back_left_joint" type="ball">
      <parent>base_link</parent>
      <child>caster_back_left_link</child>
    </joint>

    <joint name="imu_joint" type="fixed">
      <parent>base_link</parent>
      <child>imu_link</child>
      <pose>-0.032 0 0.068 0 0 0</pose>
    </joint>

    <joint name="lidar_joint" type="fixed">
      <parent>base_link</parent>
      <child>base_scan</child>
      <pose>-0.064 0 0.121 0 0 0</pose>
    </joint>

    <joint name="camera_joint" type="fixed">
      <parent>base_link</parent>
      <child>camera_link</child>
    </joint>

    <!-- Ignition Gazebo Fortress Plugins -->
    <plugin filename="libignition-gazebo-diff-drive-system.so"
            name="ignition::gazebo::systems::DiffDrive">
      <left_joint>wheel_left_joint</left_joint>
      <right_joint>wheel_right_joint</right_joint>
      <wheel_separation>0.287</wheel_separation>
      <wheel_radius>0.033</wheel_radius>
      <topic>cmd_vel</topic>
      <odom_topic>odom</odom_topic>
      <frame_id>odom</frame_id>
      <child_frame_id>base_footprint</child_frame_id>
      <tf_topic>/tf</tf_topic>
      <odom_publisher_frequency>30</odom_publisher_frequency>
    </plugin>

    <plugin filename="libignition-gazebo-joint-state-publisher-system.so"
            name="ignition::gazebo::systems::JointStatePublisher">
      <topic>joint_states</topic>
      <joint_name>wheel_left_joint</joint_name>
      <joint_name>wheel_right_joint</joint_name>
    </plugin>

  </model>
</sdf>
